<?xml version="1.0" encoding="utf-8"?>
<!-- =================================================================================== -->
<!-- |    This document was autogenerated by xacro from hyqreal.urdf.xacro             | -->
<!-- |    EDITING THIS FILE BY HAND IS NOT RECOMMENDED                                 | -->
<!-- |    @author : Siddharth Deore (sidddharth.deore@iit.it)                          | -->
<!-- =================================================================================== -->

<mujoco model="hyqreal">
    <compiler angle="radian" autolimits="true"/>
    <option cone="elliptic" impratio="100"/>
    <size njmax="500" nconmax="100"/>

    <default>
        <geom contype="1" conaffinity="1" friction="0.8 0.02 0.01" rgba="0.5 0.6 0.7 1" margin="0.001" group="0"/>

        <light castshadow="false" diffuse="1 1 1"/>
        <camera fovy="60"/>
        <joint damping="1" armature="0.01" frictionloss="0.1"/>


        <default class="visual">
            <geom type="mesh" contype="0" conaffinity="0" group="2"/>
        </default>
        <default class="collision">
            <geom group="3"/>
        </default>

    </default>

    <statistic meansize="0.29655" extent="1.58278" center="0.0252638 1.96516e-05 -0.0852795"/>
    <asset>
        <mesh name="combined_torso" file="assets/combined_torso.stl" scale="0.001 0.001 0.001"/>
        <mesh name="upperleg" file="assets/upperleg.stl" scale="0.001 0.001 0.001"/>
        <mesh name="lowerleg" file="assets/lowerleg.stl" scale="0.001 0.001 0.001"/>
    </asset>


    <worldbody>
        <body name="base" pos="0 0 0">
            <site name="imu" pos="0 0 0"/>
            <inertial pos="-0.015 -0.00186 -0.03465" quat="0.505823 0.493632 0.493714 0.506672" mass="59"
                      diaginertia="9.49239 9.01712 1.49396"/>
            <freejoint/>

            <!-- trunk visual and collision -->
            <geom class="visual" quat="0 0 0 1" type="mesh" rgba="0.3 0.3 0.3 1" mesh="combined_torso"/>
            <geom class="collision" quat="0 0 0 1" type="mesh" rgba="0.3 0.3 0.3 1" mesh="combined_torso"/>

            <!-- FL leg -->
            <body name="FL_hip" pos="0.4435 0.139 0" quat="0 0.707107 0 -0.707107">
                <inertial pos="-0.010027 -0.010608 0.003644" quat="0.0172936 0.713902 0.11116 0.69115" mass="4.97328"
                          diaginertia="0.0169092 0.0158089 0.0111439"/>
                <joint name="FL_hip_joint" pos="0 0 0" axis="0 0 1" range="-0.733038 0.401426"/>

                <body name="FL_thigh" pos="0 -0.117 0" quat="0.707107 0.707107 0 0">
                    <inertial pos="0.107987 -0.011459 -0.002121" quat="-2.79164e-05 0.728231 -0.0229726 0.684947"
                              mass="5.87793" diaginertia="0.0795119 0.0757918 0.0161323"/>
                    <joint name="FL_thigh_joint" pos="0 0 0" axis="0 0 1" range="0.261799 2.18166"/>

                    <!-- FL_upperleg visual and collision -->
                    <geom class="visual" type="mesh" rgba="1 1 0 1" mesh="upperleg"/>
                    <geom class="collision" type="mesh" rgba="1 1 0 1" mesh="upperleg"/>

                    <body name="FL_calf" pos="0.36 0 0">
                        <inertial pos="0.149302 -0.003801 -0.000624" quat="0.173193 0.683299 0.187939 0.683948"
                                  mass="1.29195" diaginertia="0.0300334 0.0289679 0.00107681"/>
                        <joint name="FL_calf_joint" pos="0 0 0" axis="0 0 1" range="-2.77001 -0.669857"/>

                        <!-- FL_lowerleg visual and collision -->
                        <geom class="visual" type="mesh" rgba="0.3 0.3 0.2 1" mesh="lowerleg"/>
                        <geom class="collision" type="mesh" rgba="0.3 0.3 0.2 1" mesh="lowerleg"/>

                        <!-- FL_foot collision -->
                        <geom class="collision" name="FL" size="0.036" pos="0.38 0 0"/>
                        <!--body name="FL_foot" pos="0.38 0 0">
                            <geom name="FL" class="collision" size="0.032" pos="0.0 0 0"/>
                        </body-->

                    </body>
                </body>
            </body>

            <!-- FR leg -->
            <body name="FR_hip" pos="0.4435 -0.139 0" quat="0.707107 0 0.707107 0">
                <inertial pos="-0.010027 -0.010608 0.003644" quat="0.0172936 0.713902 0.11116 0.69115" mass="4.97328"
                          diaginertia="0.0169092 0.0158089 0.0111439"/>
                <joint name="FR_hip_joint" pos="0 0 0" axis="0 0 1" range="-0.733038 0.401426"/>

                <body name="FR_thigh" pos="0 -0.117 0" quat="0.707107 -0.707107 0 0">
                    <inertial pos="0.107987 -0.011459 0.002121" quat="0.0229726 0.684947 2.79164e-05 0.728231"
                              mass="5.87793" diaginertia="0.0795119 0.0757918 0.0161323"/>
                    <joint name="FR_thigh_joint" pos="0 0 0" axis="0 0 1" range="0.261799 2.18166"/>

                    <!-- FR_upperleg visual and collision -->
                    <geom class="visual" type="mesh" rgba="1 1 0 1" mesh="upperleg"/>
                    <geom class="collision" type="mesh" rgba="1 1 0 1" mesh="upperleg"/>

                    <body name="FR_calf" pos="0.36 0 0">
                        <inertial pos="0.149302 -0.003801 -0.000624" quat="0.173193 0.683299 0.187939 0.683948"
                                  mass="1.29195" diaginertia="0.0300334 0.0289679 0.00107681"/>
                        <joint name="FR_calf_joint" pos="0 0 0" axis="0 0 1" range="-2.77001 -0.669857"/>

                        <!-- FR_lowerleg visual and collision -->
                        <geom class="visual" type="mesh" rgba="0.3 0.3 0.2 1" mesh="lowerleg"/>
                        <geom class="collision" type="mesh" rgba="0.3 0.3 0.2 1" mesh="lowerleg"/>

                        <!-- FR_foot collision -->
                        <geom class="collision" name="FR" size="0.032" pos="0.38 0 0"/>
                        <!--body name="FR_foot" pos="0.38 0 0">
                            <geom name="FR" class="collision" size="0.032" pos="0.0 0 0"/>
                        </body-->

                    </body>
                </body>
            </body>

            <!-- RL leg -->
            <body name="RL_hip" pos="-0.4435 0.139 0" quat="0 0.707107 0 -0.707107">
                <inertial pos="-0.010027 -0.010608 0.003644" quat="0.0172936 0.713902 0.11116 0.69115" mass="4.97328"
                          diaginertia="0.0169092 0.0158089 0.0111439"/>
                <joint name="RL_hip_joint" pos="0 0 0" axis="0 0 1" range="-0.733038 0.401426"/>

                <body name="RL_thigh" pos="0 -0.117 0" quat="0.707107 0.707107 0 0">
                    <inertial pos="0.107987 -0.011459 -0.002121" quat="-2.79164e-05 0.728231 -0.0229726 0.684947"
                              mass="5.87793" diaginertia="0.0795119 0.0757918 0.0161323"/>
                    <joint name="RL_thigh_joint" pos="0 0 0" axis="0 0 1" range="0.261799 2.18166"/>

                    <!-- RL_upperleg visual and collision -->
                    <geom type="mesh" class="visual" rgba="1 1 0 1" mesh="upperleg"/>
                    <geom type="mesh" class="collision" rgba="1 1 0 1" mesh="upperleg"/>

                    <body name="RL_calf" pos="0.36 0 0">
                        <inertial pos="0.149302 -0.003801 -0.000624" quat="0.173193 0.683299 0.187939 0.683948"
                                  mass="1.29195" diaginertia="0.0300334 0.0289679 0.00107681"/>
                        <joint name="RL_calf_joint" pos="0 0 0" axis="0 0 1" range="-2.77001 -0.669857"/>

                        <!-- RL_lowerleg visual and collision -->
                        <geom type="mesh" class="visual" rgba="0.3 0.3 0.2 1" mesh="lowerleg"/>
                        <geom type="mesh" class="collision" rgba="0.3 0.3 0.2 1" mesh="lowerleg"/>

                        <geom class="collision" name="RL" size="0.032" pos="0.38 0 0"/>
                        <!--body name="RL_foot" pos="0.38 0 0">
                            <geom name="RL" class="collision" size="0.032" pos="0.0 0 0"/>
                        </body-->

                    </body>
                </body>
            </body>

            <!-- RR leg -->
            <body name="RR_hip" pos="-0.4435 -0.139 0" quat="0.707107 0 0.707107 0">
                <inertial pos="-0.010027 -0.010608 0.003644" quat="0.0172936 0.713902 0.11116 0.69115" mass="4.97328"
                          diaginertia="0.0169092 0.0158089 0.0111439"/>
                <joint name="RR_hip_joint" pos="0 0 0" axis="0 0 1" range="-0.733038 0.401426"/>

                <body name="RR_thigh" pos="0 -0.117 0" quat="0.707107 -0.707107 0 0">
                    <inertial pos="0.107987 -0.011459 0.002121" quat="0.0229726 0.684947 2.79164e-05 0.728231"
                              mass="5.87793" diaginertia="0.0795119 0.0757918 0.0161323"/>
                    <joint name="RR_thigh_joint" pos="0 0 0" axis="0 0 1" range="0.261799 2.18166"/>

                    <!-- RR_upperleg visual and collision -->
                    <geom type="mesh" class="visual" rgba="1 1 0 1" mesh="upperleg"/>
                    <geom type="mesh" class="collision" rgba="1 1 0 1" mesh="upperleg"/>

                    <body name="RR_calf" pos="0.36 0 0">
                        <inertial pos="0.149302 -0.003801 -0.000624" quat="0.173193 0.683299 0.187939 0.683948"
                                  mass="1.29195" diaginertia="0.0300334 0.0289679 0.00107681"/>
                        <joint name="RR_calf_joint" pos="0 0 0" axis="0 0 1" range="-2.77001 -0.669857"/>

                        <!-- RR_lowerleg visual and collision -->
                        <geom type="mesh" class="visual" rgba="0.3 0.3 0.2 1" mesh="lowerleg"/>
                        <geom type="mesh" class="collision" rgba="0.3 0.3 0.2 1" mesh="lowerleg"/>

                        <!-- RR_foot collision -->
                        <geom class="collision" name="RR" size="0.032" pos="0.38 0 0"/>
                        <!--body name="RR_foot" pos="0.38 0 0">
                            <geom name="RR" class="collision" size="0.032" pos="0.0 0 0"/>
                        </body-->

                    </body>
                </body>
            </body>
        </body>
    </worldbody>

    <sensor>
        <jointpos name="FL_hip_pos" joint="FL_hip_joint"/>
        <jointpos name="FL_thigh_pos" joint="FL_thigh_joint"/>
        <jointpos name="FL_calf_pos" joint="FL_calf_joint"/>
        <jointpos name="FR_hip_pos" joint="FR_hip_joint"/>
        <jointpos name="FR_thigh_pos" joint="FR_thigh_joint"/>
        <jointpos name="FR_calf_pos" joint="FR_calf_joint"/>
        <jointpos name="RL_hip_pos" joint="RL_hip_joint"/>
        <jointpos name="RL_thigh_pos" joint="RL_thigh_joint"/>
        <jointpos name="RL_calf_pos" joint="RL_calf_joint"/>
        <jointpos name="RR_hip_pos" joint="RR_hip_joint"/>
        <jointpos name="RR_thigh_pos" joint="RR_thigh_joint"/>
        <jointpos name="RR_calf_pos" joint="RR_calf_joint"/>

        <jointvel name="FL_hip_vel" joint="FL_hip_joint"/>
        <jointvel name="FL_thigh_vel" joint="FL_thigh_joint"/>
        <jointvel name="FL_calf_vel" joint="FL_calf_joint"/>
        <jointvel name="FR_hip_vel" joint="FR_hip_joint"/>
        <jointvel name="FR_thigh_vel" joint="FR_thigh_joint"/>
        <jointvel name="FR_calf_vel" joint="FR_calf_joint"/>
        <jointvel name="RL_hip_vel" joint="RL_hip_joint"/>
        <jointvel name="RL_thigh_vel" joint="RL_thigh_joint"/>
        <jointvel name="RL_calf_vel" joint="RL_calf_joint"/>
        <jointvel name="RR_hip_vel" joint="RR_hip_joint"/>
        <jointvel name="RR_thigh_vel" joint="RR_thigh_joint"/>
        <jointvel name="RR_calf_vel" joint="RR_calf_joint"/>

        <accelerometer name="Body_Acc" site="imu"/>
        <gyro name="Body_Gyro" site="imu"/>
        <framepos name="Body_Pos" objtype="site" objname="imu"/>
        <framequat name="Body_Quat" objtype="site" objname="imu"/>
    </sensor>


    <actuator>

        <motor name="FL_hip" ctrlrange="-173.0 173.0" joint="FR_hip_joint"/>
        <motor name="FL_thigh" ctrlrange="-208 208" joint="FR_thigh_joint"/>
        <motor name="FL_calf" ctrlrange="-249 249" joint="FR_calf_joint"/>

        <motor name="FR_hip" ctrlrange="-173.0 173.0" joint="FL_hip_joint"/>
        <motor name="FR_thigh" ctrlrange="-208 208" joint="FL_thigh_joint"/>
        <motor name="FR_calf" ctrlrange="-249 249" joint="FL_calf_joint"/>

        <motor name="RL_hip" ctrlrange="-173.0 173.0" joint="RL_hip_joint"/>
        <motor name="RL_thigh" ctrlrange="-208 208" joint="RL_thigh_joint"/>
        <motor name="RL_calf" ctrlrange="-249 249" joint="RL_calf_joint"/>

        <motor name="RR_hip" ctrlrange="-173.0 173.0" joint="RR_hip_joint"/>
        <motor name="RR_thigh" ctrlrange="-208 208" joint="RR_thigh_joint"/>
        <motor name="RR_calf" ctrlrange="-249 249" joint="RR_calf_joint"/>

    </actuator>

    <keyframe>
        <key qpos='0 0 0.5 1 0 0 0 0 0.9 -1.7 0 0.9 -1.7 0 0.9 -1.7 0 0.9 -1.7'/>
    </keyframe>
</mujoco>

