<mujoco model="aliengo_description">
    <compiler angle="radian" autolimits="true"/>

    <default>
        <default class="visual">
            <geom type="mesh" contype="0" conaffinity="0" group="2"/>
        </default>
        <default class="collision">
            <geom group="3" rgba="0.2 0.2 0.2 0.5"/>
        </default>

        <default class="hip">
            <motor ctrlrange="-35.278 35.278"/>
        </default>
        <default class="thigh">
            <motor ctrlrange="-35.278 35.278"/>
        </default>
        <default class="calf">
            <motor ctrlrange="-44.4 44.4"/>
        </default>

    </default>

    <asset>
        <mesh name="base" file="assets/base.stl"/>
        <mesh name="hip" file="assets/hip.stl"/>
        <mesh name="thigh_mirror" file="assets/thigh_mirror.stl"/>
        <mesh name="calf" file="assets/calf.stl"/>
        <mesh name="thigh" file="assets/thigh.stl"/>
    </asset>


    <worldbody>

        <body name="base" pos="0 0 0.4">
            <inertial pos="0.00846406 0.00404455 -0.000762916" quat="-3.12625e-05 0.708321 0.00247254 0.705886"
                      mass="13.042" diaginertia="0.174706 0.161175 0.033357"/>
            <freejoint/>

            <!-- base visual mesh and collision -->
            <geom type="mesh" class="visual" rgba="0.2 0.2 0.2 1" mesh="base"/>
            <geom type="box" class="collision" size="0.18 0.075 0.056"/>

            <!-- modify this to add payload -->
            <!--body name="payload" pos="0 0 0">
                <geom type="box" mass="0.01" pos="0 0 0.1" size="0.05 0.05 0.05" rgba="1 0 0 0.3"/>
            </body-->

            <!-- imu and camera -->
            <site name="imu" pos="0 0 0"/>
            <camera name="robotcam" pos="0.31 -0.005 0.00292751" quat="0.4 0.4 -0.4 -0.4"/>

            <!-- FL leg -->
            <body name="FL_hip" pos="0.2399 0.051 0">
                <inertial pos="-0.022191 0.015144 -1.5e-05" quat="-0.0135493 0.706835 0.0117635 0.707151" mass="1.993"
                          diaginertia="0.00558695 0.00491009 0.00290132"/>
                <joint name="FL_hip_joint" pos="0 0 0" axis="1 0 0" limited="true" range="-1.22173 1.22173" armature="0.0062" frictionloss="0.4168" damping="0.1744"/>

                <!-- FL_hip visual mesh and collision -->
                <geom type="mesh" class="visual" rgba="0.2 0.2 0.2 1" mesh="hip"/>
                <geom type="capsule" class="collision" size="0.046 0.0209" pos="0 0.083 0"
                      quat="0.707107 0.707107 0 0"/>

                <body name="FL_thigh" pos="0 0.083 0">
                    <inertial pos="-0.005607 -0.003877 -0.048199" quat="0.717987 -0.031246 -0.0335669 0.694544"
                              mass="0.639" diaginertia="0.0058474 0.00571186 0.000324584"/>
                    <joint name="FL_thigh_joint" pos="0 0 0" axis="0 1 0" armature="0.0172" frictionloss="0.3451" damping="0.1396"/>

                    <!-- FL_thigh visual mesh and collision -->
                    <geom type="mesh" class="visual" rgba="0.2 0.2 0.2 1" mesh="thigh"/>
                    <geom type="box" class="collision" size="0.125 0.0187 0.0215" pos="0 0 -0.125"
                          quat="0.707107 0 0.707107 0"/>

                    <body name="FL_calf" pos="0 0 -0.25">
                        <inertial pos="0.00215606 4.88427e-05 -0.166671" quat="0.707462 0.00517582 0.00535172 0.706712"
                                  mass="0.267" diaginertia="0.00690975 0.00689712 5.4885e-05"/>
                        <joint name="FL_calf_joint" pos="0 0 0" axis="0 1 0" limited="true" range="-2.77507 -0.645772" armature="0.0269" frictionloss="0.4909" damping="0.1588"/>

                        <!-- FL_calf visual mesh and collision -->
                        <geom type="mesh" class="visual" rgba="0 0 0 1" mesh="calf"/>
                        <geom type="box" class="collision" size="0.125 0.0104 0.008" pos="0 0 -0.125"
                              quat="0.707107 0 0.707107 0"/>

                        <!-- FL_foot only collision -->
                        <!--geom name="FL" class="collision" size="0.0265" pos="0 0 -0.25"/-->

                        <body name="FL_foot" pos="0 0 -0.25">
                            <!-- FL_foot only collision -->
                            <geom name="FL" class="collision" size="0.0265"/>
                        </body>

                    </body>
                </body>
            </body>

            <!-- FR leg -->
            <body name="FR_hip" pos="0.2399 -0.051 0">
                <inertial pos="-0.022191 -0.015144 -1.5e-05" quat="0.0135493 0.706835 -0.0117635 0.707151" mass="1.993"
                          diaginertia="0.00558695 0.00491009 0.00290132"/>
                <joint name="FR_hip_joint" pos="0 0 0" axis="1 0 0" limited="true" range="-1.22173 1.22173" armature="0.0096" frictionloss="0.4756" damping="0.1"/>

                <!-- FR_hip visual mesh and collision -->
                <geom type="mesh" mesh="hip" class="visual" quat="0 1 0 0" rgba="0.2 0.2 0.2 1"/>
                <geom type="capsule" class="collision" size="0.046 0.0209" pos="0 -0.083 0"
                      quat="0.707107 0.707107 0 0"/>

                <body name="FR_thigh" pos="0 -0.083 0">
                    <inertial pos="-0.005607 0.003877 -0.048199" quat="0.694544 -0.0335669 -0.031246 0.717987"
                              mass="0.639" diaginertia="0.0058474 0.00571186 0.000324584"/>
                    <joint name="FR_thigh_joint" pos="0 0 0" axis="0 1 0" armature="0.0126" frictionloss="0.2558" damping="0.2542"/>

                    <!-- FR_thigh visual mesh and collision -->
                    <geom type="mesh" mesh="thigh_mirror" class="visual" rgba="0.2 0.2 0.2 1"/>
                    <geom type="box" class="collision" size="0.125 0.0187 0.0215" pos="0 0 -0.125"
                          quat="0.707107 0 0.707107 0"/>

                    <body name="FR_calf" pos="0 0 -0.25">
                        <inertial pos="0.00215606 4.88427e-05 -0.166671" quat="0.707462 0.00517582 0.00535172 0.706712"
                                  mass="0.267" diaginertia="0.00690975 0.00689712 5.4885e-05"/>
                        <joint name="FR_calf_joint" pos="0 0 0" axis="0 1 0" limited="true" range="-2.77507 -0.645772" armature="0.0170" frictionloss="0.1965" damping="0.3150"/>

                        <!-- FR_calf visual mesh and collision -->
                        <geom type="mesh" mesh="calf" class="visual" rgba="0 0 0 1"/>
                        <geom type="box" class="collision" size="0.125 0.0104 0.008" pos="0 0 -0.125"
                              quat="0.707107 0 0.707107 0"/>

                        <!-- FR_foot only collision -->
                        <!--geom name="FR" class="collision" size="0.0265" pos="0 0 -0.25"/-->

                        <body name="FR_foot" pos="0 0 -0.25">
                            <!-- FR_foot only collision -->
                            <geom name="FR" class="collision" size="0.0265"/>
                        </body>

                    </body>
                </body>
            </body>

            <!-- RL leg -->
            <body name="RL_hip" pos="-0.2399 0.051 0">
                <inertial pos="0.022191 0.015144 -1.5e-05" quat="0.0117635 0.707151 -0.0135493 0.706835" mass="1.993"
                          diaginertia="0.00558695 0.00491009 0.00290132"/>
                <joint name="RL_hip_joint" pos="0 0 0" axis="1 0 0" limited="true" range="-1.22173 1.22173" armature="0.0097" frictionloss="0.3773" damping="0.1832"/>

                <!-- RL_hip visual mesh and collision -->
                <geom type="mesh" class="visual" quat="0 0 1 0" rgba="0.2 0.2 0.2 1" mesh="hip"/>
                <geom type="capsule" class="collision" size="0.046 0.0209" pos="0 0.083 0"
                      quat="0.707107 0.707107 0 0"/>

                <body name="RL_thigh" pos="0 0.083 0">
                    <inertial pos="-0.005607 -0.003877 -0.048199" quat="0.717987 -0.031246 -0.0335669 0.694544"
                              mass="0.639" diaginertia="0.0058474 0.00571186 0.000324584"/>
                    <joint name="RL_thigh_joint" pos="0 0 0" axis="0 1 0" armature="0.0160" frictionloss="0.2892" damping="0.1884"/>

                    <!-- RL_thigh visual mesh and collision -->
                    <geom type="mesh" class="visual" rgba="0.2 0.2 0.2 1" mesh="thigh"/>
                    <geom type="box" class="collision" size="0.125 0.0187 0.0215" pos="0 0 -0.125"
                          quat="0.707107 0 0.707107 0"/>

                    <body name="RL_calf" pos="0 0 -0.25">
                        <inertial pos="0.00215606 4.88427e-05 -0.166671" quat="0.707462 0.00517582 0.00535172 0.706712"
                                  mass="0.267" diaginertia="0.00690975 0.00689712 5.4885e-05"/>
                        <joint name="RL_calf_joint" pos="0 0 0" axis="0 1 0" limited="true" range="-2.77507 -0.645772" armature="0.0233" frictionloss="0.3549" damping="0.2531"/>

                        <!-- RL_calf visual mesh and collision -->
                        <geom type="mesh" class="visual" rgba="0 0 0 1" mesh="calf"/>
                        <geom type="box" class="collision" size="0.125 0.0104 0.008" pos="0 0 -0.125"
                              quat="0.707107 0 0.707107 0"/>

                        <!-- RL_foot only collision -->
                        <!--geom name="RL" class="collision" size="0.0265" pos="0 0 -0.25"/-->
                        
                        <body name="RL_foot" pos="0 0 -0.25">
                            <!-- RL_foot only collision -->
                            <geom name="RL" class="collision" size="0.0265"/>
                        </body>

                    </body>
                </body>
            </body>

            <!-- RR leg -->
            <body name="RR_hip" pos="-0.2399 -0.051 0">
                <inertial pos="0.022191 -0.015144 -1.5e-05" quat="-0.0117635 0.707151 0.0135493 0.706835" mass="1.993"
                          diaginertia="0.00558695 0.00491009 0.00290132"/>
                <joint name="RR_hip_joint" pos="0 0 0" axis="1 0 0" limited="true" range="-1.22173 1.22173" armature="0.0119" frictionloss="0.6511" damping="0.2535"/>

                <!-- RR_hip visual mesh and collision -->
                <geom type="mesh" class="visual" quat="0 0 0 -1" rgba="0.2 0.2 0.2 1" mesh="hip"/>
                <geom type="capsule" class="collision" size="0.046 0.0209" pos="0 -0.083 0"
                      quat="0.707107 0.707107 0 0"/>

                <body name="RR_thigh" pos="0 -0.083 0">
                    <inertial pos="-0.005607 0.003877 -0.048199" quat="0.694544 -0.0335669 -0.031246 0.717987"
                              mass="0.639" diaginertia="0.0058474 0.00571186 0.000324584"/>
                    <joint name="RR_thigh_joint" pos="0 0 0" axis="0 1 0" armature="0.0150" frictionloss="0.2998" damping="0.2233"/>

                    <!-- RR_thigh visual mesh and collision -->
                    <geom type="mesh" class="visual" rgba="0.2 0.2 0.2 1" mesh="thigh_mirror"/>
                    <geom type="box" class="collision" size="0.125 0.0187 0.0215" pos="0 0 -0.125"
                          quat="0.707107 0 0.707107 0"/>

                    <body name="RR_calf" pos="0 0 -0.25">
                        <inertial pos="0.00215606 4.88427e-05 -0.166671" quat="0.707462 0.00517582 0.00535172 0.706712"
                                  mass="0.267" diaginertia="0.00690975 0.00689712 5.4885e-05"/>
                        <joint name="RR_calf_joint" pos="0 0 0" axis="0 1 0" limited="true" range="-2.77507 -0.645772" armature="0.0249" frictionloss="0.4363" damping="0.3365"/>

                        <!-- RR_calf visual mesh and collision -->
                        <geom type="mesh" class="visual" rgba="0 0 0 1" mesh="calf"/>
                        <geom type="box" class="collision" size="0.125 0.0104 0.008" pos="0 0 -0.125"
                              quat="0.707107 0 0.707107 0"/>

                        <!-- RR_foot only collision -->
                        <!--geom name="RR" class="collision" size="0.0265" pos="0 0 -0.25"/-->

                        <body name="RR_foot" pos="0 0 -0.25">
                            <!-- RR_foot only collision -->
                            <geom name="RR" class="collision" size="0.0265"/>
                        </body>

                    </body>
                </body>
            </body>
        </body>
    </worldbody>

    <actuator>       
        <motor name="FL_hip"   class="hip"    gear="1" joint="FL_hip_joint"/>
        <motor name="FL_thigh" class="thigh"  gear="1" joint="FL_thigh_joint"/>
        <motor name="FL_calf"  class="calf"   gear="1" joint="FL_calf_joint"/>
        <motor name="FR_hip"   class="hip"    gear="1" joint="FR_hip_joint"/>
        <motor name="FR_thigh" class="thigh"  gear="1" joint="FR_thigh_joint"/>
        <motor name="FR_calf"  class="calf"   gear="1" joint="FR_calf_joint"/>
        <motor name="RL_hip"   class="hip"    gear="1" joint="RL_hip_joint"/>
        <motor name="RL_thigh" class="thigh"  gear="1" joint="RL_thigh_joint"/>
        <motor name="RL_calf"  class="calf"   gear="1" joint="RL_calf_joint"/>
        <motor name="RR_hip"   class="hip"    gear="1" joint="RR_hip_joint"/>
        <motor name="RR_thigh" class="thigh"  gear="1" joint="RR_thigh_joint"/>
        <motor name="RR_calf"  class="calf"   gear="1" joint="RR_calf_joint" />
    </actuator>

    <sensor>
        <accelerometer name="imu_acc" site="imu"/>
        <gyro name="imu_gyro" site="imu"/>
        <framepos name="imu_pos" objtype="site" objname="imu"/>
        <framequat name="imu_quat" objtype="site" objname="imu"/>

        <jointpos name="FL_hip_joint_pos" joint="FL_hip_joint"/>
        <jointpos name="FL_thigh_joint_pos" joint="FL_thigh_joint"/>
        <jointpos name="FL_calf_joint_pos" joint="FL_calf_joint"/>
        <jointpos name="FR_hip_joint_pos" joint="FR_hip_joint"/>
        <jointpos name="FR_thigh_joint_pos" joint="FR_thigh_joint"/>
        <jointpos name="FR_calf_joint_pos" joint="FR_calf_joint"/>
        <jointpos name="RL_hip_joint_pos" joint="RL_hip_joint"/>
        <jointpos name="RL_thigh_joint_pos" joint="RL_thigh_joint"/>
        <jointpos name="RL_calf_joint_pos" joint="RL_calf_joint"/>
        <jointpos name="RR_hip_joint_pos" joint="RR_hip_joint"/>
        <jointpos name="RR_thigh_joint_pos" joint="RR_thigh_joint"/>
        <jointpos name="RR_calf_joint_pos" joint="RR_calf_joint"/>
    </sensor>


    <keyframe>
        <key name="home" qpos="0 0 0.35 1 0 0 0 0 0.9 -1.8 0 0.9 -1.8 0 0.9 -1.8 0 0.9 -1.8"/>
        <key name="down" qpos="0 0 0.05 1 0 0 0 0.0 1.21 -2.794 0.0 1.21 -2.794 0.0 1.21 -2.794 0.0 1.21 -2.794"/>
    </keyframe>
</mujoco>
