<?xml version="1.0" ?>
<!-- =================================================================================== -->
<!-- |    This document was autogenerated by xacro from hyqreal2_model_ordered.urdf.xacro | -->
<!-- |    EDITING THIS FILE BY HAND IS NOT RECOMMENDED                                 | -->
<!-- =================================================================================== -->
<robot name="hyq" xmlns:xacro="http://ros.org/wiki/xacro">

  <!-- Floating-base Joint -->
  <joint name="floating_base" type="floating">
    <origin rpy="0 0 0" xyz="0 0 0"/>
    <parent link="base_link"/>
    <child link="trunk"/>
  </joint>
  <!-- Links -->
  <!-- Footprint link -->
  <link name="base_link">
    <visual>
      <geometry>
        <cylinder length="0.01" radius="0.01"/>
      </geometry>
    </visual>
  </link>
  <!-- Trunk link -->
  <link name="trunk">
    <inertial>
      <origin xyz="0.0015 0.0019 -0.0014"/>
      <mass value="58.2907"/>
      <inertia ixx="1.0102" ixy="-0.0001" ixz="-0.0025" iyy="4.1869" iyz="-0.0044" izz="4.2882"/>
    </inertial>
    <visual>
      <origin rpy="0 0 3.14159265359" xyz="0 0 0"/>
      <geometry>
        <mesh filename="/home/iit.local/gturrisi/dls_ws_home/dls1/prova/src/hyqreal2_description/meshes/trunk/torso.stl" scale="0.001 0.001 0.001"/>
      </geometry>
    </visual>
    <collision>
      <origin rpy="0 0 3.14159265359" xyz="0 0 0"/>
      <geometry>
        <mesh filename="/home/iit.local/gturrisi/dls_ws_home/dls1/prova/src/hyqreal2_description/meshes/trunk/torso.stl" scale="0.001 0.001 0.001"/>
      </geometry>
    </collision>
  </link>

  <!-- Joints -->
  <!-- HAA joint -->
  <joint name="01_lf_haa_joint" type="revolute">
    <origin rpy="3.14159265359 1.57079632679 0" xyz="0.4042 0.1505 0"/>
    <parent link="trunk"/>
    <child link="01_lf_hipassembly"/>
    <axis xyz="0 0 1"/>
    <dynamics damping="0.1" friction="0"/>
    <limit effort="150.0" lower="-0.733038285838" upper="0.401425727959" velocity="12.0"/>
    <safety_controller k_position="50" k_velocity="10" soft_lower_limit="-0.733038285838" soft_upper_limit="0.401425727959"/>
  </joint>
  <!-- <xacro:property name="upper_leg_mesh_file"
                    value="${'/home/iit.local/gturrisi/dls_ws_home/dls1/prova/src/hyqreal2_description/meshes/leg/upper_leg_visual.stl'
                            if reflect_left == 1
                            else '/home/iit.local/gturrisi/dls_ws_home/dls1/prova/src/hyqreal2_description/meshes/leg/upper_leg_visual_mirrored.stl'}"/> -->
  <!-- HFE joint -->
  <joint name="01_lf_hfe_joint" type="revolute">
    <origin rpy="1.57079632679 0 0" xyz="0 -0.1636 0"/>
    <parent link="01_lf_hipassembly"/>
    <child link="01_lf_upperleg"/>
    <axis xyz="0 0 1"/>
    <dynamics damping="0.1" friction="0"/>
    <limit effort="250" lower="0.261799387799" upper="2.18166156499" velocity="12.0"/>
    <safety_controller k_position="50" k_velocity="10" soft_lower_limit="0.261799387799" soft_upper_limit="2.18166156499"/>
  </joint>
  <!-- KFE joint -->
  <joint name="01_lf_kfe_joint" type="revolute">
    <origin rpy="0 0 0" xyz="0.418 0 0"/>
    <parent link="01_lf_upperleg"/>
    <child link="01_lf_lowerleg"/>
    <axis xyz="0 0 1"/>
    <dynamics damping="0.1" friction="0"/>
    <limit effort="350" lower="-2.77001205584" upper="-0.669857366915" velocity="12.0"/>
    <safety_controller k_position="50.0" k_velocity="10.0" soft_lower_limit="-2.77001205584" soft_upper_limit="-0.669857366915"/>
  </joint>
  <!-- Foot joint -->
  <joint name="01_lf_foot_joint" type="fixed">
    <origin rpy="1.57079632679 0 -1.57079632679" xyz="0.43 0 0"/>
    <parent link="01_lf_lowerleg"/>
    <child link="01_lf_foot"/>
  </joint>
  <!-- Links -->
  <!-- Hip assembly link -->
  <link name="01_lf_hipassembly">
    <inertial>
      <origin xyz="-0.0291805 -0.0025707 0.0009034"/>
      <mass value="2.0709"/>
      <inertia ixx="0.0051712468" ixy="0.0002049916" ixz="0.0001047604" iyy="0.0048889341" iyz="4.6072e-05" izz="0.0049651854"/>
    </inertial>
    <visual>
      <origin rpy="0 -1.57079632679 -1.57079632679" xyz="0 -0.046 0"/>
      <geometry>
        <cylinder length="0.117" radius="0.0444"/>
      </geometry>
    </visual>
  </link>
  <!-- Upper leg link -->
  <link name="01_lf_upperleg">
    <inertial>
      <origin xyz="0.0659 0.0099 -0.0426"/>
      <mass value="4.0374"/>
      <inertia ixx="0.0162" ixy="0.0048" ixz="0.0112" iyy="0.0826" iyz="0.0012" izz="0.0791"/>
    </inertial>
    <visual>
      <origin rpy="0.0 0 0" xyz="0 0 0"/>
      <geometry>
        <mesh filename="/home/iit.local/gturrisi/dls_ws_home/dls1/prova/src/hyqreal2_description/meshes/leg/upper_leg_visual.stl" scale="0.001 0.001 0.001"/>
      </geometry>
    </visual>
    <collision>
      <origin rpy="0.0 0 0" xyz="0 0 0"/>
      <geometry>
        <mesh filename="/home/iit.local/gturrisi/dls_ws_home/dls1/prova/src/hyqreal2_description/meshes/leg/upper_leg_visual.stl" scale="0.001 0.001 0.001"/>
      </geometry>
    </collision>
  </link>
  <!-- Lower leg link -->
  <link name="01_lf_lowerleg">
    <inertial>
      <origin xyz="0.2561 -0.0111 2.8686e-05"/>
      <mass value="1.2253"/>
      <inertia ixx="0.0011" ixy="0.0011" ixz="-1.0812e-05" iyy="0.0436" iyz="2.31e-07" izz="0.0445"/>
    </inertial>
    <visual>
      <origin rpy="0 0 0" xyz="0 0 0"/>
      <geometry>
        <mesh filename="/home/iit.local/gturrisi/dls_ws_home/dls1/prova/src/hyqreal2_description/meshes/leg/lower_leg_visual.stl" scale="0.001 0.001 0.001"/>
      </geometry>
      <material name="white"/>
    </visual>
    <collision>
      <origin rpy="0 0 0" xyz="0 0 0"/>
      <geometry>
        <mesh filename="/home/iit.local/gturrisi/dls_ws_home/dls1/prova/src/hyqreal2_description/meshes/leg/lower_leg_visual.stl" scale="0.001 0.001 0.001"/>
      </geometry>
    </collision>
  </link>
  <!-- Foot link -->
  <link name="01_lf_foot">
    <visual>
      <origin rpy="0.0 0.0 0.0" xyz="0.0 0.0 0.0"/>
      <geometry>
        <sphere radius="0.032"/>
      </geometry>
      <material name="black"/>
    </visual>
    <collision>
      <origin rpy="0 0 0" xyz="0 0 0"/>
      <geometry>
        <sphere radius="0.032"/>
      </geometry>
    </collision>
  </link>



  <!-- Joints -->
  <!-- HAA joint -->
  <joint name="02_rf_haa_joint" type="revolute">
    <origin rpy="0 1.57079632679 0" xyz="0.4042 -0.1505 0"/>
    <parent link="trunk"/>
    <child link="02_rf_hipassembly"/>
    <axis xyz="0 0 1"/>
    <dynamics damping="0.1" friction="0"/>
    <limit effort="150.0" lower="-0.733038285838" upper="0.401425727959" velocity="12.0"/>
    <safety_controller k_position="50" k_velocity="10" soft_lower_limit="-0.733038285838" soft_upper_limit="0.401425727959"/>
  </joint>
  <!-- <xacro:property name="upper_leg_mesh_file"
                    value="${'/home/iit.local/gturrisi/dls_ws_home/dls1/prova/src/hyqreal2_description/meshes/leg/upper_leg_visual.stl'
                            if reflect_left == 1
                            else '/home/iit.local/gturrisi/dls_ws_home/dls1/prova/src/hyqreal2_description/meshes/leg/upper_leg_visual_mirrored.stl'}"/> -->
  <!-- HFE joint -->
  <joint name="02_rf_hfe_joint" type="revolute">
    <origin rpy="-1.57079632679 0 0" xyz="0 -0.1636 0"/>
    <parent link="02_rf_hipassembly"/>
    <child link="02_rf_upperleg"/>
    <axis xyz="0 0 1"/>
    <dynamics damping="0.1" friction="0"/>
    <limit effort="250" lower="0.261799387799" upper="2.18166156499" velocity="12.0"/>
    <safety_controller k_position="50" k_velocity="10" soft_lower_limit="0.261799387799" soft_upper_limit="2.18166156499"/>
  </joint>
  <!-- KFE joint -->
  <joint name="02_rf_kfe_joint" type="revolute">
    <origin rpy="0 0 0" xyz="0.418 0 0"/>
    <parent link="02_rf_upperleg"/>
    <child link="02_rf_lowerleg"/>
    <axis xyz="0 0 1"/>
    <dynamics damping="0.1" friction="0"/>
    <limit effort="350" lower="-2.77001205584" upper="-0.669857366915" velocity="12.0"/>
    <safety_controller k_position="50.0" k_velocity="10.0" soft_lower_limit="-2.77001205584" soft_upper_limit="-0.669857366915"/>
  </joint>
  <!-- Foot joint -->
  <joint name="02_rf_foot_joint" type="fixed">
    <origin rpy="1.57079632679 0 -1.57079632679" xyz="0.43 0 0"/>
    <parent link="02_rf_lowerleg"/>
    <child link="02_rf_foot"/>
  </joint>
  <!-- Links -->
  <!-- Hip assembly link -->
  <link name="02_rf_hipassembly">
    <inertial>
      <origin xyz="-0.0291805 -0.0025707 0.0009034"/>
      <mass value="2.0709"/>
      <inertia ixx="0.0051712468" ixy="0.0002049916" ixz="0.0001047604" iyy="0.0048889341" iyz="4.6072e-05" izz="0.0049651854"/>
    </inertial>
    <visual>
      <origin rpy="0 -1.57079632679 -1.57079632679" xyz="0 -0.046 0"/>
      <geometry>
        <cylinder length="0.117" radius="0.0444"/>
      </geometry>
    </visual>
  </link>
  <!-- Upper leg link -->
  <link name="02_rf_upperleg">
    <inertial>
      <origin xyz="0.0659 0.0099 0.0426"/>
      <mass value="4.0374"/>
      <inertia ixx="0.0162" ixy="0.0048" ixz="-0.0112" iyy="0.0826" iyz="-0.0012" izz="0.0791"/>
    </inertial>
    <visual>
      <origin rpy="-3.14159265359 0 0" xyz="0 0 0"/>
      <geometry>
        <mesh filename="/home/iit.local/gturrisi/dls_ws_home/dls1/prova/src/hyqreal2_description/meshes/leg/upper_leg_visual_mirrored.stl" scale="0.001 0.001 0.001"/>
      </geometry>
    </visual>
    <collision>
      <origin rpy="-3.14159265359 0 0" xyz="0 0 0"/>
      <geometry>
        <mesh filename="/home/iit.local/gturrisi/dls_ws_home/dls1/prova/src/hyqreal2_description/meshes/leg/upper_leg_visual_mirrored.stl" scale="0.001 0.001 0.001"/>
      </geometry>
    </collision>
  </link>
  <!-- Lower leg link -->
  <link name="02_rf_lowerleg">
    <inertial>
      <origin xyz="0.2561 -0.0111 2.8686e-05"/>
      <mass value="1.2253"/>
      <inertia ixx="0.0011" ixy="0.0011" ixz="-1.0812e-05" iyy="0.0436" iyz="2.31e-07" izz="0.0445"/>
    </inertial>
    <visual>
      <origin rpy="0 0 0" xyz="0 0 0"/>
      <geometry>
        <mesh filename="/home/iit.local/gturrisi/dls_ws_home/dls1/prova/src/hyqreal2_description/meshes/leg/lower_leg_visual.stl" scale="0.001 0.001 0.001"/>
      </geometry>
      <material name="white"/>
    </visual>
    <collision>
      <origin rpy="0 0 0" xyz="0 0 0"/>
      <geometry>
        <mesh filename="/home/iit.local/gturrisi/dls_ws_home/dls1/prova/src/hyqreal2_description/meshes/leg/lower_leg_visual.stl" scale="0.001 0.001 0.001"/>
      </geometry>
    </collision>
  </link>
  <!-- Foot link -->
  <link name="02_rf_foot">
    <visual>
      <origin rpy="0.0 0.0 0.0" xyz="0.0 0.0 0.0"/>
      <geometry>
        <sphere radius="0.032"/>
      </geometry>
      <material name="black"/>
    </visual>
    <collision>
      <origin rpy="0 0 0" xyz="0 0 0"/>
      <geometry>
        <sphere radius="0.032"/>
      </geometry>
    </collision>
  </link>


  <!-- Joints -->
  <!-- HAA joint -->
  <joint name="03_lh_haa_joint" type="revolute">
    <origin rpy="3.14159265359 1.57079632679 0" xyz="-0.4042 0.1505 0"/>
    <parent link="trunk"/>
    <child link="03_lh_hipassembly"/>
    <axis xyz="0 0 1"/>
    <dynamics damping="0.1" friction="0"/>
    <limit effort="150.0" lower="-0.733038285838" upper="0.401425727959" velocity="12.0"/>
    <safety_controller k_position="50" k_velocity="10" soft_lower_limit="-0.733038285838" soft_upper_limit="0.401425727959"/>
  </joint>
  <!-- <xacro:property name="upper_leg_mesh_file"
                    value="${'/home/iit.local/gturrisi/dls_ws_home/dls1/prova/src/hyqreal2_description/meshes/leg/upper_leg_visual.stl'
                            if reflect_left == 1
                            else '/home/iit.local/gturrisi/dls_ws_home/dls1/prova/src/hyqreal2_description/meshes/leg/upper_leg_visual_mirrored.stl'}"/> -->
  <!-- HFE joint -->
  <joint name="03_lh_hfe_joint" type="revolute">
    <origin rpy="1.57079632679 0 0" xyz="0 -0.1636 0"/>
    <parent link="03_lh_hipassembly"/>
    <child link="03_lh_upperleg"/>
    <axis xyz="0 0 1"/>
    <dynamics damping="0.1" friction="0"/>
    <limit effort="250" lower="0.261799387799" upper="2.18166156499" velocity="12.0"/>
    <safety_controller k_position="50" k_velocity="10" soft_lower_limit="0.261799387799" soft_upper_limit="2.18166156499"/>
  </joint>
  <!-- KFE joint -->
  <joint name="03_lh_kfe_joint" type="revolute">
    <origin rpy="0 0 0" xyz="0.418 0 0"/>
    <parent link="03_lh_upperleg"/>
    <child link="03_lh_lowerleg"/>
    <axis xyz="0 0 1"/>
    <dynamics damping="0.1" friction="0"/>
    <limit effort="350" lower="-2.77001205584" upper="-0.669857366915" velocity="12.0"/>
    <safety_controller k_position="50.0" k_velocity="10.0" soft_lower_limit="-2.77001205584" soft_upper_limit="-0.669857366915"/>
  </joint>
  <!-- Foot joint -->
  <joint name="03_lh_foot_joint" type="fixed">
    <origin rpy="1.57079632679 0 -1.57079632679" xyz="0.43 0 0"/>
    <parent link="03_lh_lowerleg"/>
    <child link="03_lh_foot"/>
  </joint>
  <!-- Links -->
  <!-- Hip assembly link -->
  <link name="03_lh_hipassembly">
    <inertial>
      <origin xyz="-0.0291805 -0.0025707 0.0009034"/>
      <mass value="2.0709"/>
      <inertia ixx="0.0051712468" ixy="0.0002049916" ixz="0.0001047604" iyy="0.0048889341" iyz="4.6072e-05" izz="0.0049651854"/>
    </inertial>
    <visual>
      <origin rpy="0 -1.57079632679 -1.57079632679" xyz="0 -0.046 0"/>
      <geometry>
        <cylinder length="0.117" radius="0.0444"/>
      </geometry>
    </visual>
  </link>
  <!-- Upper leg link -->
  <link name="03_lh_upperleg">
    <inertial>
      <origin xyz="0.0659 0.0099 -0.0426"/>
      <mass value="4.0374"/>
      <inertia ixx="0.0162" ixy="0.0048" ixz="0.0112" iyy="0.0826" iyz="0.0012" izz="0.0791"/>
    </inertial>
    <visual>
      <origin rpy="0.0 0 0" xyz="0 0 0"/>
      <geometry>
        <mesh filename="/home/iit.local/gturrisi/dls_ws_home/dls1/prova/src/hyqreal2_description/meshes/leg/upper_leg_visual.stl" scale="0.001 0.001 0.001"/>
      </geometry>
    </visual>
    <collision>
      <origin rpy="0.0 0 0" xyz="0 0 0"/>
      <geometry>
        <mesh filename="/home/iit.local/gturrisi/dls_ws_home/dls1/prova/src/hyqreal2_description/meshes/leg/upper_leg_visual.stl" scale="0.001 0.001 0.001"/>
      </geometry>
    </collision>
  </link>
  <!-- Lower leg link -->
  <link name="03_lh_lowerleg">
    <inertial>
      <origin xyz="0.2561 -0.0111 2.8686e-05"/>
      <mass value="1.2253"/>
      <inertia ixx="0.0011" ixy="0.0011" ixz="-1.0812e-05" iyy="0.0436" iyz="2.31e-07" izz="0.0445"/>
    </inertial>
    <visual>
      <origin rpy="0 0 0" xyz="0 0 0"/>
      <geometry>
        <mesh filename="/home/iit.local/gturrisi/dls_ws_home/dls1/prova/src/hyqreal2_description/meshes/leg/lower_leg_visual.stl" scale="0.001 0.001 0.001"/>
      </geometry>
      <material name="white"/>
    </visual>
    <collision>
      <origin rpy="0 0 0" xyz="0 0 0"/>
      <geometry>
        <mesh filename="/home/iit.local/gturrisi/dls_ws_home/dls1/prova/src/hyqreal2_description/meshes/leg/lower_leg_visual.stl" scale="0.001 0.001 0.001"/>
      </geometry>
    </collision>
  </link>
  <!-- Foot link -->
  <link name="03_lh_foot">
    <visual>
      <origin rpy="0.0 0.0 0.0" xyz="0.0 0.0 0.0"/>
      <geometry>
        <sphere radius="0.032"/>
      </geometry>
      <material name="black"/>
    </visual>
    <collision>
      <origin rpy="0 0 0" xyz="0 0 0"/>
      <geometry>
        <sphere radius="0.032"/>
      </geometry>
    </collision>
  </link>


  <!-- Joints -->
  <!-- HAA joint -->
  <joint name="04_rh_haa_joint" type="revolute">
    <origin rpy="0 1.57079632679 0" xyz="-0.4042 -0.1505 0"/>
    <parent link="trunk"/>
    <child link="04_rh_hipassembly"/>
    <axis xyz="0 0 1"/>
    <dynamics damping="0.1" friction="0"/>
    <limit effort="150.0" lower="-0.733038285838" upper="0.401425727959" velocity="12.0"/>
    <safety_controller k_position="50" k_velocity="10" soft_lower_limit="-0.733038285838" soft_upper_limit="0.401425727959"/>
  </joint>
  <!-- <xacro:property name="upper_leg_mesh_file"
                    value="${'/home/iit.local/gturrisi/dls_ws_home/dls1/prova/src/hyqreal2_description/meshes/leg/upper_leg_visual.stl'
                            if reflect_left == 1
                            else '/home/iit.local/gturrisi/dls_ws_home/dls1/prova/src/hyqreal2_description/meshes/leg/upper_leg_visual_mirrored.stl'}"/> -->
  <!-- HFE joint -->
  <joint name="04_rh_hfe_joint" type="revolute">
    <origin rpy="-1.57079632679 0 0" xyz="0 -0.1636 0"/>
    <parent link="04_rh_hipassembly"/>
    <child link="04_rh_upperleg"/>
    <axis xyz="0 0 1"/>
    <dynamics damping="0.1" friction="0"/>
    <limit effort="250" lower="0.261799387799" upper="2.18166156499" velocity="12.0"/>
    <safety_controller k_position="50" k_velocity="10" soft_lower_limit="0.261799387799" soft_upper_limit="2.18166156499"/>
  </joint>
  <!-- KFE joint -->
  <joint name="04_rh_kfe_joint" type="revolute">
    <origin rpy="0 0 0" xyz="0.418 0 0"/>
    <parent link="04_rh_upperleg"/>
    <child link="04_rh_lowerleg"/>
    <axis xyz="0 0 1"/>
    <dynamics damping="0.1" friction="0"/>
    <limit effort="350" lower="-2.77001205584" upper="-0.669857366915" velocity="12.0"/>
    <safety_controller k_position="50.0" k_velocity="10.0" soft_lower_limit="-2.77001205584" soft_upper_limit="-0.669857366915"/>
  </joint>
  <!-- Foot joint -->
  <joint name="04_rh_foot_joint" type="fixed">
    <origin rpy="1.57079632679 0 -1.57079632679" xyz="0.43 0 0"/>
    <parent link="04_rh_lowerleg"/>
    <child link="04_rh_foot"/>
  </joint>
  <!-- Links -->
  <!-- Hip assembly link -->
  <link name="04_rh_hipassembly">
    <inertial>
      <origin xyz="-0.0291805 -0.0025707 0.0009034"/>
      <mass value="2.0709"/>
      <inertia ixx="0.0051712468" ixy="0.0002049916" ixz="0.0001047604" iyy="0.0048889341" iyz="4.6072e-05" izz="0.0049651854"/>
    </inertial>
    <visual>
      <origin rpy="0 -1.57079632679 -1.57079632679" xyz="0 -0.046 0"/>
      <geometry>
        <cylinder length="0.117" radius="0.0444"/>
      </geometry>
    </visual>
  </link>
  <!-- Upper leg link -->
  <link name="04_rh_upperleg">
    <inertial>
      <origin xyz="0.0659 0.0099 0.0426"/>
      <mass value="4.0374"/>
      <inertia ixx="0.0162" ixy="0.0048" ixz="-0.0112" iyy="0.0826" iyz="-0.0012" izz="0.0791"/>
    </inertial>
    <visual>
      <origin rpy="-3.14159265359 0 0" xyz="0 0 0"/>
      <geometry>
        <mesh filename="/home/iit.local/gturrisi/dls_ws_home/dls1/prova/src/hyqreal2_description/meshes/leg/upper_leg_visual_mirrored.stl" scale="0.001 0.001 0.001"/>
      </geometry>
    </visual>
    <collision>
      <origin rpy="-3.14159265359 0 0" xyz="0 0 0"/>
      <geometry>
        <mesh filename="/home/iit.local/gturrisi/dls_ws_home/dls1/prova/src/hyqreal2_description/meshes/leg/upper_leg_visual_mirrored.stl" scale="0.001 0.001 0.001"/>
      </geometry>
    </collision>
  </link>
  <!-- Lower leg link -->
  <link name="04_rh_lowerleg">
    <inertial>
      <origin xyz="0.2561 -0.0111 2.8686e-05"/>
      <mass value="1.2253"/>
      <inertia ixx="0.0011" ixy="0.0011" ixz="-1.0812e-05" iyy="0.0436" iyz="2.31e-07" izz="0.0445"/>
    </inertial>
    <visual>
      <origin rpy="0 0 0" xyz="0 0 0"/>
      <geometry>
        <mesh filename="/home/iit.local/gturrisi/dls_ws_home/dls1/prova/src/hyqreal2_description/meshes/leg/lower_leg_visual.stl" scale="0.001 0.001 0.001"/>
      </geometry>
      <material name="white"/>
    </visual>
    <collision>
      <origin rpy="0 0 0" xyz="0 0 0"/>
      <geometry>
        <mesh filename="/home/iit.local/gturrisi/dls_ws_home/dls1/prova/src/hyqreal2_description/meshes/leg/lower_leg_visual.stl" scale="0.001 0.001 0.001"/>
      </geometry>
    </collision>
  </link>
  <!-- Foot link -->
  <link name="04_rh_foot">
    <visual>
      <origin rpy="0.0 0.0 0.0" xyz="0.0 0.0 0.0"/>
      <geometry>
        <sphere radius="0.032"/>
      </geometry>
      <material name="black"/>
    </visual>
    <collision>
      <origin rpy="0 0 0" xyz="0 0 0"/>
      <geometry>
        <sphere radius="0.032"/>
      </geometry>
    </collision>
  </link>

</robot>

